Workbook

Sheet README
A1: HOW TO USE THIS TEMPLATE
A2: Colour rule | B2: BLUE text = you type it. BLACK text = a formula, do not overwrite.
A3: Header rule | B3: GREEN header = input column. NAVY header = derived column.
A4: Sample rows | B4: Every sheet has sample rows so you can see the formulas working. Delete them and paste your own data over the top.
A5: Extending | B5: Formulas are pre-filled and blank-guarded to row 201 (Dim_Fund, Fact_Work), 401 (Fact_Milestone), 60 (Dim_Analyst). For more, select the last formula row and drag down.
A6: Time entry | B6: Cut-offs as real times (04:30), not text. Actual events as full date-times.
A8: DECISIONS BUILT INTO THIS VERSION
A9: EUC adjustment | B9: Fifth product flag. EUC = 1 moves 5 points toward reconciliation, the same direction as ETD. Recon_Pct now ranges 55 to 85, so NAV calculation can fall to 15% of required time on a fund carrying ETD, both OTC types and EUC without PFC. Those funds have almost no room after the pricing gate — check the Feasibility_Flag on them first.
A10: Strategic client | B10: Captured as a Yes/No flag in Dim_Fund column E. The derived Client_Tier column turns it into Strategic or Non-strategic for use as a dashboard label and slicer. Use the YESNO transform if your export holds it as Y/N.
A11: A feed that does not apply | B11: Never leave the cut-off blank — blank reads as 00:00, which gives that fund the largest slack in the book and sorts it to the bottom of the watchlist. Set Has_<feed>_Process to No and put the PRICING cut-off in the time cell. Slack becomes zero, the feed is treated as never binding, and the slack, rank and watchlist columns all show n/a.
A12: A cut-off you do not know | B12: Different problem. Enter a conservative estimate and set Cutoff_Data_Quality to Estimated. Filter those funds out of supplier analysis — an estimated pricing cut-off produces phantom SLA breaches you do not want in a conversation with the pricing team.
A13: Pricing or client cut-off missing | B13: Not a gap, an exclusion. Those two anchor every calculation. Leave the fund out rather than guess.
A14: Custody and TA arrivals — NOT captured | B14: They carry 5–8 hours of slack before the pricing gate, so their lateness is absorbed and never reaches NAV. Chasing email trails for them buys nothing. Their cut-offs stay in Dim_Fund because they still define the slack calculation.
A15: Broker — ETA, not a cut-off | B15: Broker_ETA is the supplier's own estimate, not a contractual deadline. Treat 'on time vs ETA' with care: it says nothing about whether the ETA was reasonable. Once you have actuals, systematic optimism in the ETA is its own finding.
A16: Broker actuals — watchlist only | B16: Capture them only for funds flagged CAPTURE in Dim_Fund. Everything else has too much slack for a late broker to bind.
A17: Pricing — mandatory | B17: Slack of zero by definition, already in your system. Every minute late is a minute on NAV.
A18: Analyst — two fields, two jobs | B18: Dim_Fund.Default_Analyst_ID is the normal owner, used for PLANNED capacity. Fact_Work.Maker_ID is who actually did it, from the maker record, used for ACTUAL capacity. The gap between them is the reassignment rate.
A19: Checker — captured, unbudgeted | B19: The 450 minutes covers MAKER effort only. Check time is real time in someone's day that no capacity figure allows for. Dim_Analyst shows it in its own column and adds it into True_Load_Mins.
A21: SHEETS
A22: Constants | B22: 20.38, 450, the five % adjustments, and the broker watchlist threshold.
A23: Dim_Team | B23: One row per team. Shift start, shifts, capacity.
A24: Dim_Signoff | B24: Three rows. Oversight and Client tails are PLACEHOLDERS — not yet agreed.
A25: Dim_Fund | B25: One row per fund. 19 inputs, 23 derived. v4.5 adds 9 derived columns (BC to BK).
A26: Dim_Analyst | B26: One row per analyst, 3 inputs. Planned load, actual load, check load and reassignment all calculate themselves.
A27: Fact_Milestone | B27: One row per fund per day per feed. Pricing always; Broker only for watchlist funds.
A28: Fact_Work | B28: One row per fund per day. 11 inputs, 18 derived. v4.5 adds 26 Power BI columns (BA to BZ).
A29: Checks | B29: Run after loading. Every check has a target.
A31: BUILD IN PHASES
A32: Phase 1 | B32: Constants + Dim_Team + Dim_Fund + Dim_Analyst. No event data at all. Gives planned load, utilisation, the feasibility flag and the broker watchlist. Start here.
A33: Phase 2 | B33: Add Fact_Milestone (pricing only, to begin with). Gives the whole pricing critical-path view.
A34: Phase 3 | B34: Add Fact_Work. Maker ID comes free from the system record, so actual capacity and reassignment are available immediately — not a later phase.
A36: STILL OPEN
A37: Oversight and client tails | B37: No agreed target. Measure the actual for three months, take the 80th percentile, use that as a working assumption and negotiate from evidence.
A38: Shift assignment for two-shift teams | B38: Not captured. Build on single-shift teams and report the rest as unmeasurable — that is a legitimate output and a better case for capturing it than asking in the abstract.
A39: Check time budget | B39: If checking turns out to be a material share of the day, the 450 needs revisiting or checking needs its own weightage. The Check_Mins_PerDay column tells you whether it is material.
A41: TWO TRAPS WORTH CHECKING
A42: Pricing arrival meaning | B42: Is it when the file landed, or when someone marked it received? The second includes human lag and overstates supplier delay. Matters if you show these numbers to the pricing team.
A43: Delivered_DT meaning | B43: Is it FA completion or post-sign-off delivery? These differ on roughly 30% of funds and mixing them corrupts every breach rate.
A45: STATUS LOG — HOW FACT_WORK IS NOW BUILT
A46: What you paste | B46: Status_Log, long format: one row per status change, with Date, Fund_ID, Status text, Timestamp and the Person name. Paste the whole log — only four statuses are read, everything else is ignored.
...

Sheet Constants
A1: CONSTANT | B1: VALUE | C1: NOTES
A2: FTE denominator | B2: 20.38 | C2: INPUT — confirmed constant across all funds.
A3: Daily capacity (minutes) | B3: 450 | C3: INPUT — one analyst's day. MAKER EFFORT ONLY. Checking is not inside this number.
A4: Minutes per weightage unit | B4: =B3/B2 -> 22.080471 | C4: FORMULA — 450 / 20.38 = 22.08.
A6: Base reconciliation % | B6: 60 | C6: INPUT — fund with none of the four products.
A7: ETD adjustment | B7: 5 | C7: INPUT
A8: OTC (non-CFD) adjustment | B8: 5 | C8: INPUT
A9: OTC (CFD) adjustment | B9: 10 | C9: INPUT
A10: PFC adjustment | B10: -5 | C10: INPUT — negative, moves the boundary toward NAV calculation.
A11: EUC adjustment | B11: 5 | C11: INPUT — positive, moves the boundary toward reconciliation (same direction as ETD).
A13: Business days in Fact_Work | B13: =IF(COUNT(Fact_Work!$B:$B)=0,1,NETWORKDAYS(MIN(Fact_Work!$B:$B),MAX(Fact_Work!$B:$B))) -> 3 | C13: FORMULA — used to convert total actual minutes into a per-day figure.
A14: Broker slack watchlist threshold (mins) | B14: 90 | C14: INPUT — funds with less broker margin than this are the only ones where a late broker can bind. Capture broker actuals for these funds only.
A15: Peak percentile | B15: 0.75 | C15: INPUT — a time slot counts as Peak when its funds-due-per-day is at or above this percentile of the busy slots.
A16: WARNING | C16: Changing any INPUT moves every fund's target at once, including history. Version-control before editing.
A17: Thin slack threshold (mins) | B17: 0 | C17: INPUT — v4.5. A custody, TA or broker feed is THIN when its slack to the pricing cut-off is at or below this. 0 = zero tolerance: thin only when the feed's cut-off is at or after the pricing cut-off, so any lateness reaches NAV directly. Separate from the broker watchlist threshold in B14.
A18: Shift length (hrs) | B18: 9 | C18: INPUT — v4.5. Hours on desk including breaks, the same for every team. Shift end = Dim_Team shift start + this. Places each maker on the clock for the Team load by hour chart.

Sheet Dim_Team
A1: Team_ID | B1: Team_Name | C1: Shift_Start | D1: Shifts_In_Team | E1: Daily_Capacity_Mins | F1: Shift_Start_Hr | G1: Shift_End_Hr
A2: TM01 | B2: Equity Ops | C2: 0.375 | D2: 1 | E2: 450 | F2: =IF($A2="","",HOUR($C2)+MINUTE($C2)/60) -> 9 | G2: =IF($A2="","",$F2+Constants!$B$18) -> 18
A3: TM02 | B3: Fixed Income Ops | C3: 0.375 | D3: 1 | E3: 450 | F3: =IF($A3="","",HOUR($C3)+MINUTE($C3)/60) -> 9 | G3: =IF($A3="","",$F3+Constants!$B$18) -> 18
A4: TM03 | B4: Multi-Asset Ops | C4: 0.41666667 | D4: 1 | E4: 450 | F4: =IF($A4="","",HOUR($C4)+MINUTE($C4)/60) -> 10 | G4: =IF($A4="","",$F4+Constants!$B$18) -> 19
A5: TM04 | B5: Derivatives Ops | C5: 0.375 | D5: 2 | E5: 450 | F5: =IF($A5="","",HOUR($C5)+MINUTE($C5)/60) -> 9 | G5: =IF($A5="","",$F5+Constants!$B$18) -> 18
F6: =IF($A6="","",HOUR($C6)+MINUTE($C6)/60) | G6: =IF($A6="","",$F6+Constants!$B$18)
F7: =IF($A7="","",HOUR($C7)+MINUTE($C7)/60) | G7: =IF($A7="","",$F7+Constants!$B$18)
F8: =IF($A8="","",HOUR($C8)+MINUTE($C8)/60) | G8: =IF($A8="","",$F8+Constants!$B$18)
F9: =IF($A9="","",HOUR($C9)+MINUTE($C9)/60) | G9: =IF($A9="","",$F9+Constants!$B$18)
F10: =IF($A10="","",HOUR($C10)+MINUTE($C10)/60) | G10: =IF($A10="","",$F10+Constants!$B$18)
F11: =IF($A11="","",HOUR($C11)+MINUTE($C11)/60) | G11: =IF($A11="","",$F11+Constants!$B$18)
F12: =IF($A12="","",HOUR($C12)+MINUTE($C12)/60) | G12: =IF($A12="","",$F12+Constants!$B$18)
F13: =IF($A13="","",HOUR($C13)+MINUTE($C13)/60) | G13: =IF($A13="","",$F13+Constants!$B$18)
F14: =IF($A14="","",HOUR($C14)+MINUTE($C14)/60) | G14: =IF($A14="","",$F14+Constants!$B$18)
F15: =IF($A15="","",HOUR($C15)+MINUTE($C15)/60) | G15: =IF($A15="","",$F15+Constants!$B$18)
F16: =IF($A16="","",HOUR($C16)+MINUTE($C16)/60) | G16: =IF($A16="","",$F16+Constants!$B$18)
F17: =IF($A17="","",HOUR($C17)+MINUTE($C17)/60) | G17: =IF($A17="","",$F17+Constants!$B$18)
... F39: =IF($A39="","",HOUR($C39)+MINUTE($C39)/60) | G39: =IF($A39="","",$F39+Constants!$B$18)

Sheet Dim_Signoff
A1: Signoff_Model | B1: Responsible_Party | C1: Planned_Tail_Mins | D1: Status
A2: FA | B2: FA team — checker only, no external step | C2: 0 | D2: Defined
A3: Oversight | B3: Internal oversight team | C3: 25 | D3: NOT AGREED — placeholder
A4: Client | B4: Client approves | C4: 46 | D4: NOT AGREED — placeholder

Sheet Dim_Fund
A1: Fund_ID | B1: Fund_Name | C1: Client_ID | D1: Client_Name | E1: Strategic_Client | F1: Team_ID | G1: Default_Analyst_Name | H1: Weightage | I1: ETD | J1: OTC_nonCFD | K1: OTC_CFD | L1: PFC | M1: EUC | N1: Has_Custody_Process | O1: Has_TA_Process | P1: Has_Broker_Process | Q1: Custody_Cutoff | R1: TA_Cutoff | S1: Broker_ETA | T1: Pricing_Cutoff | U1: TOP_ID | V1: Client_Cutoff | W1: NAV_Deadline | X1: Signoff_Model | Y1: Cutoff_Data_Quality | Z1: Recon_Pct | AA1: NAV_Pct | AB1: Required_Mins | AC1: Recon_Mins | AD1: NAV_Mins | AE1: Custody_Cutoff_Hr | AF1: TA_Cutoff_Hr | AG1: Broker_ETA_Hr | AH1: Pricing_Cutoff_Hr | AI1: Client_Cutoff_Hr | AJ1: NAV_Deadline_Hr | AK1: Shift_Start_Hr | AL1: Planned_Tail_Mins | AM1: Slack_Custody_Mins | AN1: Slack_TA_Mins | AO1: Slack_Broker_Mins | AP1: Avail_Recon_Mins | AQ1: Avail_NAV_Mins | AR1: Recon_Feasible | AS1: NAV_Feasible | AT1: Feasibility_Flag | AU1: Broker_Watchlist | AV1: Broker_Slack_Rank | AW1: Client_Tier | AX1: Runs_Observed | AY1: NAV_Frequency_Observed | AZ1: TOP_Binding_Cutoff_Hr | BA1: Cutoff_Vs_TOP_Mins | BB1: TOP_Cutoff_Risk | BC1: Client_First_In_TOP | BD1: Broker_Dependent | BE1: Thin_Custody_Slack | BF1: Thin_TA_Slack | BG1: Thin_Broker_Slack | BH1: Custody_Slack_Group | BI1: Slack_Custody_Num | BJ1: Slack_TA_Num | BK1: Slack_Broker_Num
A2: FD-1001 | B2: Sample Fund 1001 | C2: CL01 | D2: Meridian Pensions | E2: Yes | F2: TM01 | G2: Lim Wei Ming | H2: 2.152 | I2: 1 | J2: 0 | K2: 0 | L2: 1 | M2: 0 | N2: Yes | O2: No | P2: No | Q2: 0.20237179 | R2: 0.52066418 | S2: 0.52066418 | T2: 0.52066418 | U2: TOP-EQ1 | V2: 0.69703251 | W2: 0.72185538 | X2: FA | Y2: Estimated | Z2: =IF($A2="","",Constants!$B$6+$I2*Constants!$B$7+$J2*Constants!$B$8+$K2*Constants!$B$9+$L2*Constants!$B$10+$M2*Constants!$B$11) -> 60 | AA2: =IF($A2="","",100-Z2) -> 40 | AB2: =IF($A2="","",ROUND($H2*Constants!$B$4,1)) -> 47.5 | AC2: =IF($A2="","",ROUND(AB2*Z2/100,1)) -> 28.5 | AD2: =IF($A2="","",ROUND(AB2*AA2/100,1)) -> 19 | AE2: =IF($A2="","",HOUR($Q2)+MINUTE($Q2)/60) -> 4.85 | AF2: =IF($A2="","",HOUR($R2)+MINUTE($R2)/60) -> 12.483333 | AG2: =IF($A2="","",HOUR($S2)+MINUTE($S2)/60) -> 12.483333 | AH2: =IF($A2="","",HOUR($T2)+MINUTE($T2)/60) -> 12.483333 | AI2: =IF($A2="","",HOUR($V2)+MINUTE($V2)/60) -> 16.716667 | AJ2: =IF($A2="","",HOUR($W2)+MINUTE($W2)/60) -> 17.316667 | AK2: =IF($A2="","",VLOOKUP($F2,Dim_Team!$A:$F,6,0)) -> 9 | AL2: =IF($A2="","",VLOOKUP($X2,Dim_Signoff!$A:$C,3,0)) -> 0 | AM2: =IF($A2="","",IF($N2="No","n/a",ROUND((AH2-AE2)*60,0))) -> 458 | AN2: =IF($A2="","",IF($O2="No","n/a",ROUND((AH2-AF2)*60,0))) -> n/a | AO2: =IF($A2="","",IF($P2="No","n/a",ROUND((AH2-AG2)*60,0))) -> n/a | AP2: =IF($A2="","",ROUND((AH2-AK2)*60,0)) -> 209 | AQ2: =IF($A2="","",ROUND((AI2-AH2)*60,0)) -> 254 | AR2: =IF($A2="","",IF(AP2>=AC2,"Yes","No")) -> Yes | AS2: =IF($A2="","",IF(AQ2>=AD2+AL2,"Yes","No")) -> Yes | AT2: =IF($A2="","",IF(AND(AR2="Yes",AS2="Yes"),"OK","REVIEW")) -> OK | AU2: =IF($A2="","",IF($P2="No","Not applicable",IF(AO2<Constants!$B$14,"CAPTURE","Not needed"))) -> Not applicable | AV2: =IF($A2="","",IF($P2="No","n/a",RANK(AO2,AO:AO,1))) -> n/a | AW2: =IF($A2="","",IF(UPPER($E2)="YES","Strategic","Non-strategic")) -> Strategic | AX2: =IF($A2="","",COUNTIFS(Fact_Work!$C:$C,$A2)) -> 3 | AY2: =IF($A2="","",IF(AX2=0,"Not seen",IF(AX2>=Constants!$B$13*0.6,"Daily",IF(AX2>=Constants!$B$13*0.12,"Weekly","Monthly or ad hoc")))) -> Daily | AZ2: =IF($A2="","",IFERROR(VLOOKUP($U2,Dim_TOP!$A:$H,8,0),"")) -> 11.65 | BA2: =IF($A2="","",IFERROR(ROUND((AH2-AZ2)*60,0),"")) -> 50 | BB2: =IF($A2="","",IF(BA2="","",IF(BA2<=0,"Sets the deadline","Later than peers by "&BA2&" min"))) -> Later than peers by 50 min | BC2: =IF($A2="","",IF($U2="",0,IF(COUNTIFS($U$2:$U2,$U2,$C$2:$C2,$C2)=1,1,0))) -> 1 | BD2: =IF($A2="","",IF(UPPER($P2)="YES","Yes","No")) -> No | BE2: =IF($A2="","",IF($N2="No","n/a",IF(AM2<=Constants!$B$17,"Yes","No"))) -> No | BF2: =IF($A2="","",IF($O2="No","n/a",IF(AN2<=Constants!$B$17,"Yes","No"))) -> n/a | BG2: =IF($A2="","",IF($P2="No","n/a",IF(AO2<=Constants!$B$17,"Yes","No"))) -> n/a | BH2: =IF($A2="","",IF($N2="No","No custody process",IF(BE2="Yes","Thin custody slack","Ample custody slack"))) -> Ample custody slack | BI2: =IF($A2="","",IF($N2="No","",AM2)) -> 458 | BJ2: =IF($A2="","",IF($O2="No","",AN2)) | BK2: =IF($A2="","",IF($P2="No","",AO2))
A3: FD-1002 | B3: Sample Fund 1002 | C3: CL02 | D3: Northgate Insurance | E3: Yes | F3: TM01 | G3: Siti Noraini | H3: 1.213 | I3: 0 | J3: 0 | K3: 0 | L3: 0 | M3: 1 | N3: Yes | O3: Yes | P3: Yes | Q3: 0.19558832 | R3: 0.15141525 | S3: 0.34989132 | T3: 0.51935645 | U3: TOP-FI1 | V3: 0.68414656 | W3: 0.71053446 | X3: FA | Y3: Confirmed | Z3: =IF($A3="","",Constants!$B$6+$I3*Constants!$B$7+$J3*Constants!$B$8+$K3*Constants!$B$9+$L3*Constants!$B$10+$M3*Constants!$B$11) -> 65 | AA3: =IF($A3="","",100-Z3) -> 35 | AB3: =IF($A3="","",ROUND($H3*Constants!$B$4,1)) -> 26.8 | AC3: =IF($A3="","",ROUND(AB3*Z3/100,1)) -> 17.4 | AD3: =IF($A3="","",ROUND(AB3*AA3/100,1)) -> 9.4 | AE3: =IF($A3="","",HOUR($Q3)+MINUTE($Q3)/60) -> 4.6833333 | AF3: =IF($A3="","",HOUR($R3)+MINUTE($R3)/60) -> 3.6333333 | AG3: =IF($A3="","",HOUR($S3)+MINUTE($S3)/60) -> 8.3833333 | AH3: =IF($A3="","",HOUR($T3)+MINUTE($T3)/60) -> 12.45 | AI3: =IF($A3="","",HOUR($V3)+MINUTE($V3)/60) -> 16.416667 | AJ3: =IF($A3="","",HOUR($W3)+MINUTE($W3)/60) -> 17.05 | AK3: =IF($A3="","",VLOOKUP($F3,Dim_Team!$A:$F,6,0)) -> 9 | AL3: =IF($A3="","",VLOOKUP($X3,Dim_Signoff!$A:$C,3,0)) -> 0 | AM3: =IF($A3="","",IF($N3="No","n/a",ROUND((AH3-AE3)*60,0))) -> 466 | AN3: =IF($A3="","",IF($O3="No","n/a",ROUND((AH3-AF3)*60,0))) -> 529 | AO3: =IF($A3="","",IF($P3="No","n/a",ROUND((AH3-AG3)*60,0))) -> 244 | AP3: =IF($A3="","",ROUND((AH3-AK3)*60,0)) -> 207 | AQ3: =IF($A3="","",ROUND((AI3-AH3)*60,0)) -> 238 | AR3: =IF($A3="","",IF(AP3>=AC3,"Yes","No")) -> Yes | AS3: =IF($A3="","",IF(AQ3>=AD3+AL3,"Yes","No")) -> Yes | AT3: =IF($A3="","",IF(AND(AR3="Yes",AS3="Yes"),"OK","REVIEW")) -> OK | AU3: =IF($A3="","",IF($P3="No","Not applicable",IF(AO3<Constants!$B$14,"CAPTURE","Not needed"))) -> Not needed | AV3: =IF($A3="","",IF($P3="No","n/a",RANK(AO3,AO:AO,1))) -> 5 | AW3: =IF($A3="","",IF(UPPER($E3)="YES","Strategic","Non-strategic")) -> Strategic | AX3: =IF($A3="","",COUNTIFS(Fact_Work!$C:$C,$A3)) -> 3 | AY3: =IF($A3="","",IF(AX3=0,"Not seen",IF(AX3>=Constants!$B$13*0.6,"Daily",IF(AX3>=Constants!$B$13*0.12,"Weekly","Monthly or ad hoc")))) -> Daily | AZ3: =IF($A3="","",IFERROR(VLOOKUP($U3,Dim_TOP!$A:$H,8,0),"")) -> 12.45 | BA3: =IF($A3="","",IFERROR(ROUND((AH3-AZ3)*60,0),"")) -> 0 | BB3: =IF($A3="","",IF(BA3="","",IF(BA3<=0,"Sets the deadline","Later than peers by "&BA3&" min"))) -> Sets the deadline | BC3: =IF($A3="","",IF($U3="",0,IF(COUNTIFS($U$2:$U3,$U3,$C$2:$C3,$C3)=1,1,0))) -> 1 | BD3: =IF($A3="","",IF(UPPER($P3)="YES","Yes","No")) -> Yes | BE3: =IF($A3="","",IF($N3="No","n/a",IF(AM3<=Constants!$B$17,"Yes","No"))) -> No | BF3: =IF($A3="","",IF($O3="No","n/a",IF(AN3<=Constants!$B$17,"Yes","No"))) -> No | BG3: =IF($A3="","",IF($P3="No","n/a",IF(AO3<=Constants!$B$17,"Yes","No"))) -> No | BH3: =IF($A3="","",IF($N3="No","No custody process",IF(BE3="Yes","Thin custody slack","Ample custody slack"))) -> Ample custody slack | BI3: =IF($A3="","",IF($N3="No","",AM3)) -> 466 | BJ3: =IF($A3="","",IF($O3="No","",AN3)) -> 529 | BK3: =IF($A3="","",IF($P3="No","",AO3)) -> 244
A4: FD-1003 | B4: Sample Fund 1003 | C4: CL03 | D4: Halvern Wealth | E4: No | F4: TM02 | G4: Raj Kumar | H4: 2.073 | I4: 0 | J4: 0 | K4: 0 | L4: 0 | M4: 0 | N4: Yes | O4: Yes | P4: Yes | Q4: 0.18913262 | R4: 0.19178209 | S4: 0.31743308 | T4: 0.48878378 | U4: TOP-MA1 | V4: 0.66347521 | W4: 0.69532609 | X4: FA | Y4: Confirmed | Z4: =IF($A4="","",Constants!$B$6+$I4*Constants!$B$7+$J4*Constants!$B$8+$K4*Constants!$B$9+$L4*Constants!$B$10+$M4*Constants!$B$11) -> 60 | AA4: =IF($A4="","",100-Z4) -> 40 | AB4: =IF($A4="","",ROUND($H4*Constants!$B$4,1)) -> 45.8 | AC4: =IF($A4="","",ROUND(AB4*Z4/100,1)) -> 27.5 | AD4: =IF($A4="","",ROUND(AB4*AA4/100,1)) -> 18.3 | AE4: =IF($A4="","",HOUR($Q4)+MINUTE($Q4)/60) -> 4.5333333 | AF4: =IF($A4="","",HOUR($R4)+MINUTE($R4)/60) -> 4.6 | AG4: =IF($A4="","",HOUR($S4)+MINUTE($S4)/60) -> 7.6166667 | AH4: =IF($A4="","",HOUR($T4)+MINUTE($T4)/60) -> 11.716667 | AI4: =IF($A4="","",HOUR($V4)+MINUTE($V4)/60) -> 15.916667 | AJ4: =IF($A4="","",HOUR($W4)+MINUTE($W4)/60) -> 16.683333 | AK4: =IF($A4="","",VLOOKUP($F4,Dim_Team!$A:$F,6,0)) -> 9 | AL4: =IF($A4="","",VLOOKUP($X4,Dim_Signoff!$A:$C,3,0)) -> 0 | AM4: =IF($A4="","",IF($N4="No","n/a",ROUND((AH4-AE4)*60,0))) -> 431 | AN4: =IF($A4="","",IF($O4="No","n/a",ROUND((AH4-AF4)*60,0))) -> 427 | AO4: =IF($A4="","",IF($P4="No","n/a",ROUND((AH4-AG4)*60,0))) -> 246 | AP4: =IF($A4="","",ROUND((AH4-AK4)*60,0)) -> 163 | AQ4: =IF($A4="","",ROUND((AI4-AH4)*60,0)) -> 252 | AR4: =IF($A4="","",IF(AP4>=AC4,"Yes","No")) -> Yes | AS4: =IF($A4="","",IF(AQ4>=AD4+AL4,"Yes","No")) -> Yes | AT4: =IF($A4="","",IF(AND(AR4="Yes",AS4="Yes"),"OK","REVIEW")) -> OK | AU4: =IF($A4="","",IF($P4="No","Not applicable",IF(AO4<Constants!$B$14,"CAPTURE","Not needed"))) -> Not needed | AV4: =IF($A4="","",IF($P4="No","n/a",RANK(AO4,AO:AO,1))) -> 6 | AW4: =IF($A4="","",IF(UPPER($E4)="YES","Strategic","Non-strategic")) -> Non-strategic | AX4: =IF($A4="","",COUNTIFS(Fact_Work!$C:$C,$A4)) -> 3 | AY4: =IF($A4="","",IF(AX4=0,"Not seen",IF(AX4>=Constants!$B$13*0.6,"Daily",IF(AX4>=Constants!$B$13*0.12,"Weekly","Monthly or ad hoc")))) -> Daily | AZ4: =IF($A4="","",IFERROR(VLOOKUP($U4,Dim_TOP!$A:$H,8,0),"")) -> 11.716667 | BA4: =IF($A4="","",IFERROR(ROUND((AH4-AZ4)*60,0),"")) -> 0 | BB4: =IF($A4="","",IF(BA4="","",IF(BA4<=0,"Sets the deadline","Later than peers by "&BA4&" min"))) -> Sets the deadline | BC4: =IF($A4="","",IF($U4="",0,IF(COUNTIFS($U$2:$U4,$U4,$C$2:$C4,$C4)=1,1,0))) -> 1 | BD4: =IF($A4="","",IF(UPPER($P4)="YES","Yes","No")) -> Yes | BE4: =IF($A4="","",IF($N4="No","n/a",IF(AM4<=Constants!$B$17,"Yes","No"))) -> No | BF4: =IF($A4="","",IF($O4="No","n/a",IF(AN4<=Constants!$B$17,"Yes","No"))) -> No | BG4: =IF($A4="","",IF($P4="No","n/a",IF(AO4<=Constants!$B$17,"Yes","No"))) -> No | BH4: =IF($A4="","",IF($N4="No","No custody process",IF(BE4="Yes","Thin custody slack","Ample custody slack"))) -> Ample custody slack | BI4: =IF($A4="","",IF($N4="No","",AM4)) -> 431 | BJ4: =IF($A4="","",IF($O4="No","",AN4)) -> 427 | BK4: =IF($A4="","",IF($P4="No","",AO4)) -> 246
A5: FD-1004 | B5: Sample Fund 1004 | C5: CL01 | D5: Meridian Pensions | E5: Yes | F5: TM03 | G5: Chen Xiao | H5: 2.099 | I5: 0 | J5: 0 | K5: 0 | L5: 0 | M5: 0 | N5: Yes | O5: Yes | P5: Yes | Q5: 0.18626602 | R5: 0.16115303 | S5: 0.31727212 | T5: 0.52841758 | U5: TOP-ALT | V5: 0.7071355 | W5: 0.73348044 | X5: Oversight | Y5: Confirmed | Z5: =IF($A5="","",Constants!$B$6+$I5*Constants!$B$7+$J5*Constants!$B$8+$K5*Constants!$B$9+$L5*Constants!$B$10+$M5*Constants!$B$11) -> 60 | AA5: =IF($A5="","",100-Z5) -> 40 | AB5: =IF($A5="","",ROUND($H5*Constants!$B$4,1)) -> 46.3 | AC5: =IF($A5="","",ROUND(AB5*Z5/100,1)) -> 27.8 | AD5: =IF($A5="","",ROUND(AB5*AA5/100,1)) -> 18.5 | AE5: =IF($A5="","",HOUR($Q5)+MINUTE($Q5)/60) -> 4.4666667 | AF5: =IF($A5="","",HOUR($R5)+MINUTE($R5)/60) -> 3.8666667 | AG5: =IF($A5="","",HOUR($S5)+MINUTE($S5)/60) -> 7.6 | AH5: =IF($A5="","",HOUR($T5)+MINUTE($T5)/60) -> 12.666667 | AI5: =IF($A5="","",HOUR($V5)+MINUTE($V5)/60) -> 16.966667 | AJ5: =IF($A5="","",HOUR($W5)+MINUTE($W5)/60) -> 17.6 | AK5: =IF($A5="","",VLOOKUP($F5,Dim_Team!$A:$F,6,0)) -> 10 | AL5: =IF($A5="","",VLOOKUP($X5,Dim_Signoff!$A:$C,3,0)) -> 25 | AM5: =IF($A5="","",IF($N5="No","n/a",ROUND((AH5-AE5)*60,0))) -> 492 | AN5: =IF($A5="","",IF($O5="No","n/a",ROUND((AH5-AF5)*60,0))) -> 528 | AO5: =IF($A5="","",IF($P5="No","n/a",ROUND((AH5-AG5)*60,0))) -> 304 | AP5: =IF($A5="","",ROUND((AH5-AK5)*60,0)) -> 160 | AQ5: =IF($A5="","",ROUND((AI5-AH5)*60,0)) -> 258 | AR5: =IF($A5="","",IF(AP5>=AC5,"Yes","No")) -> Yes | AS5: =IF($A5="","",IF(AQ5>=AD5+AL5,"Yes","No")) -> Yes | AT5: =IF($A5="","",IF(AND(AR5="Yes",AS5="Yes"),"OK","REVIEW")) -> OK | AU5: =IF($A5="","",IF($P5="No","Not applicable",IF(AO5<Constants!$B$14,"CAPTURE","Not needed"))) -> Not needed | AV5: =IF($A5="","",IF($P5="No","n/a",RANK(AO5,AO:AO,1))) -> 8 | AW5: =IF($A5="","",IF(UPPER($E5)="YES","Strategic","Non-strategic")) -> Strategic | AX5: =IF($A5="","",COUNTIFS(Fact_Work!$C:$C,$A5)) -> 3 | AY5: =IF($A5="","",IF(AX5=0,"Not seen",IF(AX5>=Constants!$B$13*0.6,"Daily",IF(AX5>=Constants!$B$13*0.12,"Weekly","Monthly or ad hoc")))) -> Daily | AZ5: =IF($A5="","",IFERROR(VLOOKUP($U5,Dim_TOP!$A:$H,8,0),"")) -> 11.633333 | BA5: =IF($A5="","",IFERROR(ROUND((AH5-AZ5)*60,0),"")) -> 62 | BB5: =IF($A5="","",IF(BA5="","",IF(BA5<=0,"Sets the deadline","Later than peers by "&BA5&" min"))) -> Later than peers by 62 min | BC5: =IF($A5="","",IF($U5="",0,IF(COUNTIFS($U$2:$U5,$U5,$C$2:$C5,$C5)=1,1,0))) -> 1 | BD5: =IF($A5="","",IF(UPPER($P5)="YES","Yes","No")) -> Yes | BE5: =IF($A5="","",IF($N5="No","n/a",IF(AM5<=Constants!$B$17,"Yes","No"))) -> No | BF5: =IF($A5="","",IF($O5="No","n/a",IF(AN5<=Constants!$B$17,"Yes","No"))) -> No | BG5: =IF($A5="","",IF($P5="No","n/a",IF(AO5<=Constants!$B$17,"Yes","No"))) -> No | BH5: =IF($A5="","",IF($N5="No","No custody process",IF(BE5="Yes","Thin custody slack","Ample custody slack"))) -> Ample custody slack | BI5: =IF($A5="","",IF($N5="No","",AM5)) -> 492 | BJ5: =IF($A5="","",IF($O5="No","",AN5)) -> 528 | BK5: =IF($A5="","",IF($P5="No","",AO5)) -> 304
A6: FD-1005 | B6: Sample Fund 1005 | C6: CL02 | D6: Northgate Insurance | E6: Yes | F6: TM03 | G6: Aisha Rahman | H6: 1.597 | I6: 0 | J6: 0 | K6: 0 | L6: 0 | M6: 1 | N6: Yes | O6: No | P6: Yes | Q6: 0.19102841 | R6: 0.54287619 | S6: 0.2938606 | T6: 0.54287619 | U6: TOP-EQ1 | V6: 0.68369544 | W6: 0.7172464 | X6: Client | Y6: Confirmed | Z6: =IF($A6="","",Constants!$B$6+$I6*Constants!$B$7+$J6*Constants!$B$8+$K6*Constants!$B$9+$L6*Constants!$B$10+$M6*Constants!$B$11) -> 65 | AA6: =IF($A6="","",100-Z6) -> 35 | AB6: =IF($A6="","",ROUND($H6*Constants!$B$4,1)) -> 35.3 | AC6: =IF($A6="","",ROUND(AB6*Z6/100,1)) -> 22.9 | AD6: =IF($A6="","",ROUND(AB6*AA6/100,1)) -> 12.4 | AE6: =IF($A6="","",HOUR($Q6)+MINUTE($Q6)/60) -> 4.5833333 | AF6: =IF($A6="","",HOUR($R6)+MINUTE($R6)/60) -> 13.016667 | AG6: =IF($A6="","",HOUR($S6)+MINUTE($S6)/60) -> 7.05 | AH6: =IF($A6="","",HOUR($T6)+MINUTE($T6)/60) -> 13.016667 | AI6: =IF($A6="","",HOUR($V6)+MINUTE($V6)/60) -> 16.4 | AJ6: =IF($A6="","",HOUR($W6)+MINUTE($W6)/60) -> 17.2 | AK6: =IF($A6="","",VLOOKUP($F6,Dim_Team!$A:$F,6,0)) -> 10 | AL6: =IF($A6="","",VLOOKUP($X6,Dim_Signoff!$A:$C,3,0)) -> 46 | AM6: =IF($A6="","",IF($N6="No","n/a",ROUND((AH6-AE6)*60,0))) -> 506 | AN6: =IF($A6="","",IF($O6="No","n/a",ROUND((AH6-AF6)*60,0))) -> n/a | AO6: =IF($A6="","",IF($P6="No","n/a",ROUND((AH6-AG6)*60,0))) -> 358 | AP6: =IF($A6="","",ROUND((AH6-AK6)*60,0)) -> 181 | AQ6: =IF($A6="","",ROUND((AI6-AH6)*60,0)) -> 203 | AR6: =IF($A6="","",IF(AP6>=AC6,"Yes","No")) -> Yes | AS6: =IF($A6="","",IF(AQ6>=AD6+AL6,"Yes","No")) -> Yes | AT6: =IF($A6="","",IF(AND(AR6="Yes",AS6="Yes"),"OK","REVIEW")) -> OK | AU6: =IF($A6="","",IF($P6="No","Not applicable",IF(AO6<Constants!$B$14,"CAPTURE","Not needed"))) -> Not needed | AV6: =IF($A6="","",IF($P6="No","n/a",RANK(AO6,AO:AO,1))) -> 10 | AW6: =IF($A6="","",IF(UPPER($E6)="YES","Strategic","Non-strategic")) -> Strategic | AX6: =IF($A6="","",COUNTIFS(Fact_Work!$C:$C,$A6)) -> 3 | AY6: =IF($A6="","",IF(AX6=0,"Not seen",IF(AX6>=Constants!$B$13*0.6,"Daily",IF(AX6>=Constants!$B$13*0.12,"Weekly","Monthly or ad hoc")))) -> Daily | AZ6: =IF($A6="","",IFERROR(VLOOKUP($U6,Dim_TOP!$A:$H,8,0),"")) -> 11.65 | BA6: =IF($A6="","",IFERROR(ROUND((AH6-AZ6)*60,0),"")) -> 82 | BB6: =IF($A6="","",IF(BA6="","",IF(BA6<=0,"Sets the deadline","Later than peers by "&BA6&" min"))) -> Later than peers by 82 min | BC6: =IF($A6="","",IF($U6="",0,IF(COUNTIFS($U$2:$U6,$U6,$C$2:$C6,$C6)=1,1,0))) -> 1 | BD6: =IF($A6="","",IF(UPPER($P6)="YES","Yes","No")) -> Yes | BE6: =IF($A6="","",IF($N6="No","n/a",IF(AM6<=Constants!$B$17,"Yes","No"))) -> No | BF6: =IF($A6="","",IF($O6="No","n/a",IF(AN6<=Constants!$B$17,"Yes","No"))) -> n/a | BG6: =IF($A6="","",IF($P6="No","n/a",IF(AO6<=Constants!$B$17,"Yes","No"))) -> No | BH6: =IF($A6="","",IF($N6="No","No custody process",IF(BE6="Yes","Thin custody slack","Ample custody slack"))) -> Ample custody slack | BI6: =IF($A6="","",IF($N6="No","",AM6)) -> 506 | BJ6: =IF($A6="","",IF($O6="No","",AN6)) | BK6: =IF($A6="","",IF($P6="No","",AO6)) -> 358
A7: FD-1006 | B7: Sample Fund 1006 | C7: CL03 | D7: Halvern Wealth | E7: No | F7: TM04 | G7: Daniel Tan | H7: 1.147 | I7: 1 | J7: 0 | K7: 0 | L7: 1 | M7: 0 | N7: Yes | O7: Yes | P7: Yes | Q7: 0.1969941 | R7: 0.16218888 | S7: 0.49486561 | T7: 0.55317194 | U7: TOP-FI1 | V7: 0.73934149 | W7: 0.76631603 | X7: FA | Y7: Confirmed | Z7: =IF($A7="","",Constants!$B$6+$I7*Constants!$B$7+$J7*Constants!$B$8+$K7*Constants!$B$9+$L7*Constants!$B$10+$M7*Constants!$B$11) -> 60 | AA7: =IF($A7="","",100-Z7) -> 40 | AB7: =IF($A7="","",ROUND($H7*Constants!$B$4,1)) -> 25.3 | AC7: =IF($A7="","",ROUND(AB7*Z7/100,1)) -> 15.2 | AD7: =IF($A7="","",ROUND(AB7*AA7/100,1)) -> 10.1 | AE7: =IF($A7="","",HOUR($Q7)+MINUTE($Q7)/60) -> 4.7166667 | AF7: =IF($A7="","",HOUR($R7)+MINUTE($R7)/60) -> 3.8833333 | AG7: =IF($A7="","",HOUR($S7)+MINUTE($S7)/60) -> 11.866667 | AH7: =IF($A7="","",HOUR($T7)+MINUTE($T7)/60) -> 13.266667 | AI7: =IF($A7="","",HOUR($V7)+MINUTE($V7)/60) -> 17.733333 | AJ7: =IF($A7="","",HOUR($W7)+MINUTE($W7)/60) -> 18.383333 | AK7: =IF($A7="","",VLOOKUP($F7,Dim_Team!$A:$F,6,0)) -> 9 | AL7: =IF($A7="","",VLOOKUP($X7,Dim_Signoff!$A:$C,3,0)) -> 0 | AM7: =IF($A7="","",IF($N7="No","n/a",ROUND((AH7-AE7)*60,0))) -> 513 | AN7: =IF($A7="","",IF($O7="No","n/a",ROUND((AH7-AF7)*60,0))) -> 563 | AO7: =IF($A7="","",IF($P7="No","n/a",ROUND((AH7-AG7)*60,0))) -> 84 | AP7: =IF($A7="","",ROUND((AH7-AK7)*60,0)) -> 256 | AQ7: =IF($A7="","",ROUND((AI7-AH7)*60,0)) -> 268 | AR7: =IF($A7="","",IF(AP7>=AC7,"Yes","No")) -> Yes | AS7: =IF($A7="","",IF(AQ7>=AD7+AL7,"Yes","No")) -> Yes | AT7: =IF($A7="","",IF(AND(AR7="Yes",AS7="Yes"),"OK","REVIEW")) -> OK | AU7: =IF($A7="","",IF($P7="No","Not applicable",IF(AO7<Constants!$B$14,"CAPTURE","Not needed"))) -> CAPTURE | AV7: =IF($A7="","",IF($P7="No","n/a",RANK(AO7,AO:AO,1))) -> 2 | AW7: =IF($A7="","",IF(UPPER($E7)="YES","Strategic","Non-strategic")) -> Non-strategic | AX7: =IF($A7="","",COUNTIFS(Fact_Work!$C:$C,$A7)) -> 3 | AY7: =IF($A7="","",IF(AX7=0,"Not seen",IF(AX7>=Constants!$B$13*0.6,"Daily",IF(AX7>=Constants!$B$13*0.12,"Weekly","Monthly or ad hoc")))) -> Daily | AZ7: =IF($A7="","",IFERROR(VLOOKUP($U7,Dim_TOP!$A:$H,8,0),"")) -> 12.45 | BA7: =IF($A7="","",IFERROR(ROUND((AH7-AZ7)*60,0),"")) -> 49 | BB7: =IF($A7="","",IF(BA7="","",IF(BA7<=0,"Sets the deadline","Later than peers by "&BA7&" min"))) -> Later than peers by 49 min | BC7: =IF($A7="","",IF($U7="",0,IF(COUNTIFS($U$2:$U7,$U7,$C$2:$C7,$C7)=1,1,0))) -> 1 | BD7: =IF($A7="","",IF(UPPER($P7)="YES","Yes","No")) -> Yes | BE7: =IF($A7="","",IF($N7="No","n/a",IF(AM7<=Constants!$B$17,"Yes","No"))) -> No | BF7: =IF($A7="","",IF($O7="No","n/a",IF(AN7<=Constants!$B$17,"Yes","No"))) -> No | BG7: =IF($A7="","",IF($P7="No","n/a",IF(AO7<=Constants!$B$17,"Yes","No"))) -> No | BH7: =IF($A7="","",IF($N7="No","No custody process",IF(BE7="Yes","Thin custody slack","Ample custody slack"))) -> Ample custody slack | BI7: =IF($A7="","",IF($N7="No","",AM7)) -> 513 | BJ7: =IF($A7="","",IF($O7="No","",AN7)) -> 563 | BK7: =IF($A7="","",IF($P7="No","",AO7)) -> 84
A8: FD-1007 | B8: Sample Fund 1007 | C8: CL01 | D8: Meridian Pensions | E8: Yes | F8: TM01 | G8: Lim Wei Ming | H8: 1.347 | I8: 0 | J8: 1 | K8: 1 | L8: 1 | M8: 0 | N8: Yes | O8: Yes | P8: No | Q8: 0.14851954 | R8: 0.19505622 | S8: 0.54673606 | T8: 0.54673606 | U8: TOP-MA1 | V8: 0.72372753 | W8: 0.76242641 | X8: FA | Y8: Confirmed | Z8: =IF($A8="","",Constants!$B$6+$I8*Constants!$B$7+$J8*Constants!$B$8+$K8*Constants!$B$9+$L8*Constants!$B$10+$M8*Constants!$B$11) -> 70 | AA8: =IF($A8="","",100-Z8) -> 30 | AB8: =IF($A8="","",ROUND($H8*Constants!$B$4,1)) -> 29.7 | AC8: =IF($A8="","",ROUND(AB8*Z8/100,1)) -> 20.8 | AD8: =IF($A8="","",ROUND(AB8*AA8/100,1)) -> 8.9 | AE8: =IF($A8="","",HOUR($Q8)+MINUTE($Q8)/60) -> 3.55 | AF8: =IF($A8="","",HOUR($R8)+MINUTE($R8)/60) -> 4.6666667 | AG8: =IF($A8="","",HOUR($S8)+MINUTE($S8)/60) -> 13.116667 | AH8: =IF($A8="","",HOUR($T8)+MINUTE($T8)/60) -> 13.116667 | AI8: =IF($A8="","",HOUR($V8)+MINUTE($V8)/60) -> 17.366667 | AJ8: =IF($A8="","",HOUR($W8)+MINUTE($W8)/60) -> 18.283333 | AK8: =IF($A8="","",VLOOKUP($F8,Dim_Team!$A:$F,6,0)) -> 9 | AL8: =IF($A8="","",VLOOKUP($X8,Dim_Signoff!$A:$C,3,0)) -> 0 | AM8: =IF($A8="","",IF($N8="No","n/a",ROUND((AH8-AE8)*60,0))) -> 574 | AN8: =IF($A8="","",IF($O8="No","n/a",ROUND((AH8-AF8)*60,0))) -> 507 | AO8: =IF($A8="","",IF($P8="No","n/a",ROUND((AH8-AG8)*60,0))) -> n/a | AP8: =IF($A8="","",ROUND((AH8-AK8)*60,0)) -> 247 | AQ8: =IF($A8="","",ROUND((AI8-AH8)*60,0)) -> 255 | AR8: =IF($A8="","",IF(AP8>=AC8,"Yes","No")) -> Yes | AS8: =IF($A8="","",IF(AQ8>=AD8+AL8,"Yes","No")) -> Yes | AT8: =IF($A8="","",IF(AND(AR8="Yes",AS8="Yes"),"OK","REVIEW")) -> OK | AU8: =IF($A8="","",IF($P8="No","Not applicable",IF(AO8<Constants!$B$14,"CAPTURE","Not needed"))) -> Not applicable | AV8: =IF($A8="","",IF($P8="No","n/a",RANK(AO8,AO:AO,1))) -> n/a | AW8: =IF($A8="","",IF(UPPER($E8)="YES","Strategic","Non-strategic")) -> Strategic | AX8: =IF($A8="","",COUNTIFS(Fact_Work!$C:$C,$A8)) -> 3 | AY8: =IF($A8="","",IF(AX8=0,"Not seen",IF(AX8>=Constants!$B$13*0.6,"Daily",IF(AX8>=Constants!$B$13*0.12,"Weekly","Monthly or ad hoc")))) -> Daily | AZ8: =IF($A8="","",IFERROR(VLOOKUP($U8,Dim_TOP!$A:$H,8,0),"")) -> 11.716667 | BA8: =IF($A8="","",IFERROR(ROUND((AH8-AZ8)*60,0),"")) -> 84 | BB8: =IF($A8="","",IF(BA8="","",IF(BA8<=0,"Sets the deadline","Later than peers by "&BA8&" min"))) -> Later than peers by 84 min | BC8: =IF($A8="","",IF($U8="",0,IF(COUNTIFS($U$2:$U8,$U8,$C$2:$C8,$C8)=1,1,0))) -> 1 | BD8: =IF($A8="","",IF(UPPER($P8)="YES","Yes","No")) -> No | BE8: =IF($A8="","",IF($N8="No","n/a",IF(AM8<=Constants!$B$17,"Yes","No"))) -> No | BF8: =IF($A8="","",IF($O8="No","n/a",IF(AN8<=Constants!$B$17,"Yes","No"))) -> No | BG8: =IF($A8="","",IF($P8="No","n/a",IF(AO8<=Constants!$B$17,"Yes","No"))) -> n/a | BH8: =IF($A8="","",IF($N8="No","No custody process",IF(BE8="Yes","Thin custody slack","Ample custody slack"))) -> Ample custody slack | BI8: =IF($A8="","",IF($N8="No","",AM8)) -> 574 | BJ8: =IF($A8="","",IF($O8="No","",AN8)) -> 507 | BK8: =IF($A8="","",IF($P8="No","",AO8))
A9: FD-1008 | B9: Sample Fund 1008 | C9: CL02 | D9: Northgate Insurance | E9: Yes | F9: TM01 | G9: Siti Noraini | H9: 1.769 | I9: 0 | J9: 0 | K9: 1 | L9: 0 | M9: 1 | N9: Yes | O9: Yes | P9: Yes | Q9: 0.1874934 | R9: 0.16795178 | S9: 0.33133422 | T9: 0.49271241 | U9: TOP-ALT | V9: 0.67259672 | W9: 0.69955729 | X9: FA | Y9: Estimated | Z9: =IF($A9="","",Constants!$B$6+$I9*Constants!$B$7+$J9*Constants!$B$8+$K9*Constants!$B$9+$L9*Constants!$B$10+$M9*Constants!$B$11) -> 75 | AA9: =IF($A9="","",100-Z9) -> 25 | AB9: =IF($A9="","",ROUND($H9*Constants!$B$4,1)) -> 39.1 | AC9: =IF($A9="","",ROUND(AB9*Z9/100,1)) -> 29.3 | AD9: =IF($A9="","",ROUND(AB9*AA9/100,1)) -> 9.8 | AE9: =IF($A9="","",HOUR($Q9)+MINUTE($Q9)/60) -> 4.4833333 | AF9: =IF($A9="","",HOUR($R9)+MINUTE($R9)/60) -> 4.0166667 | AG9: =IF($A9="","",HOUR($S9)+MINUTE($S9)/60) -> 7.95 | AH9: =IF($A9="","",HOUR($T9)+MINUTE($T9)/60) -> 11.816667 | AI9: =IF($A9="","",HOUR($V9)+MINUTE($V9)/60) -> 16.133333 | AJ9: =IF($A9="","",HOUR($W9)+MINUTE($W9)/60) -> 16.783333 | AK9: =IF($A9="","",VLOOKUP($F9,Dim_Team!$A:$F,6,0)) -> 9 | AL9: =IF($A9="","",VLOOKUP($X9,Dim_Signoff!$A:$C,3,0)) -> 0 | AM9: =IF($A9="","",IF($N9="No","n/a",ROUND((AH9-AE9)*60,0))) -> 440 | AN9: =IF($A9="","",IF($O9="No","n/a",ROUND((AH9-AF9)*60,0))) -> 468 | AO9: =IF($A9="","",IF($P9="No","n/a",ROUND((AH9-AG9)*60,0))) -> 232 | AP9: =IF($A9="","",ROUND((AH9-AK9)*60,0)) -> 169 | AQ9: =IF($A9="","",ROUND((AI9-AH9)*60,0)) -> 259 | AR9: =IF($A9="","",IF(AP9>=AC9,"Yes","No")) -> Yes | AS9: =IF($A9="","",IF(AQ9>=AD9+AL9,"Yes","No")) -> Yes | AT9: =IF($A9="","",IF(AND(AR9="Yes",AS9="Yes"),"OK","REVIEW")) -> OK | AU9: =IF($A9="","",IF($P9="No","Not applicable",IF(AO9<Constants!$B$14,"CAPTURE","Not needed"))) -> Not needed | AV9: =IF($A9="","",IF($P9="No","n/a",RANK(AO9,AO:AO,1))) -> 4 | AW9: =IF($A9="","",IF(UPPER($E9)="YES","Strategic","Non-strategic")) -> Strategic | AX9: =IF($A9="","",COUNTIFS(Fact_Work!$C:$C,$A9)) -> 1 | AY9: =IF($A9="","",IF(AX9=0,"Not seen",IF(AX9>=Constants!$B$13*0.6,"Daily",IF(AX9>=Constants!$B$13*0.12,"Weekly","Monthly or ad hoc")))) -> Weekly | AZ9: =IF($A9="","",IFERROR(VLOOKUP($U9,Dim_TOP!$A:$H,8,0),"")) -> 11.633333 | BA9: =IF($A9="","",IFERROR(ROUND((AH9-AZ9)*60,0),"")) -> 11 | BB9: =IF($A9="","",IF(BA9="","",IF(BA9<=0,"Sets the deadline","Later than peers by "&BA9&" min"))) -> Later than peers by 11 min | BC9: =IF($A9="","",IF($U9="",0,IF(COUNTIFS($U$2:$U9,$U9,$C$2:$C9,$C9)=1,1,0))) -> 1 | BD9: =IF($A9="","",IF(UPPER($P9)="YES","Yes","No")) -> Yes | BE9: =IF($A9="","",IF($N9="No","n/a",IF(AM9<=Constants!$B$17,"Yes","No"))) -> No | BF9: =IF($A9="","",IF($O9="No","n/a",IF(AN9<=Constants!$B$17,"Yes","No"))) -> No | BG9: =IF($A9="","",IF($P9="No","n/a",IF(AO9<=Constants!$B$17,"Yes","No"))) -> No | BH9: =IF($A9="","",IF($N9="No","No custody process",IF(BE9="Yes","Thin custody slack","Ample custody slack"))) -> Ample custody slack | BI9: =IF($A9="","",IF($N9="No","",AM9)) -> 440 | BJ9: =IF($A9="","",IF($O9="No","",AN9)) -> 468 | BK9: =IF($A9="","",IF($P9="No","",AO9)) -> 232
A10: FD-1009 | B10: Sample Fund 1009 | C10: CL03 | D10: Halvern Wealth | E10: No | F10: TM02 | G10: Raj Kumar | H10: 1.487 | I10: 0 | J10: 1 | K10: 0 | L10: 0 | M10: 0 | N10: Yes | O10: No | P10: Yes | Q10: 0.17932946 | R10: 0.48564405 | S10: 0.30941221 | T10: 0.48564405 | U10: TOP-EQ1 | V10: 0.63247362 | W10: 0.66810583 | X10: Oversight | Y10: Confirmed | Z10: =IF($A10="","",Constants!$B$6+$I10*Constants!$B$7+$J10*Constants!$B$8+$K10*Constants!$B$9+$L10*Constants!$B$10+$M10*Constants!$B$11) -> 65 | AA10: =IF($A10="","",100-Z10) -> 35 | AB10: =IF($A10="","",ROUND($H10*Constants!$B$4,1)) -> 32.8 | AC10: =IF($A10="","",ROUND(AB10*Z10/100,1)) -> 21.3 | AD10: =IF($A10="","",ROUND(AB10*AA10/100,1)) -> 11.5 | AE10: =IF($A10="","",HOUR($Q10)+MINUTE($Q10)/60) -> 4.3 | AF10: =IF($A10="","",HOUR($R10)+MINUTE($R10)/60) -> 11.65 | AG10: =IF($A10="","",HOUR($S10)+MINUTE($S10)/60) -> 7.4166667 | AH10: =IF($A10="","",HOUR($T10)+MINUTE($T10)/60) -> 11.65 | AI10: =IF($A10="","",HOUR($V10)+MINUTE($V10)/60) -> 15.166667 | AJ10: =IF($A10="","",HOUR($W10)+MINUTE($W10)/60) -> 16.033333 | AK10: =IF($A10="","",VLOOKUP($F10,Dim_Team!$A:$F,6,0)) -> 9 | AL10: =IF($A10="","",VLOOKUP($X10,Dim_Signoff!$A:$C,3,0)) -> 25 | AM10: =IF($A10="","",IF($N10="No","n/a",ROUND((AH10-AE10)*60,0))) -> 441 | AN10: =IF($A10="","",IF($O10="No","n/a",ROUND((AH10-AF10)*60,0))) -> n/a | AO10: =IF($A10="","",IF($P10="No","n/a",ROUND((AH10-AG10)*60,0))) -> 254 | AP10: =IF($A10="","",ROUND((AH10-AK10)*60,0)) -> 159 | AQ10: =IF($A10="","",ROUND((AI10-AH10)*60,0)) -> 211 | AR10: =IF($A10="","",IF(AP10>=AC10,"Yes","No")) -> Yes | AS10: =IF($A10="","",IF(AQ10>=AD10+AL10,"Yes","No")) -> Yes | AT10: =IF($A10="","",IF(AND(AR10="Yes",AS10="Yes"),"OK","REVIEW")) -> OK | AU10: =IF($A10="","",IF($P10="No","Not applicable",IF(AO10<Constants!$B$14,"CAPTURE","Not needed"))) -> Not needed | AV10: =IF($A10="","",IF($P10="No","n/a",RANK(AO10,AO:AO,1))) -> 7 | AW10: =IF($A10="","",IF(UPPER($E10)="YES","Strategic","Non-strategic")) -> Non-strategic | AX10: =IF($A10="","",COUNTIFS(Fact_Work!$C:$C,$A10)) -> 1 | AY10: =IF($A10="","",IF(AX10=0,"Not seen",IF(AX10>=Constants!$B$13*0.6,"Daily",IF(AX10>=Constants!$B$13*0.12,"Weekly","Monthly or ad hoc")))) -> Weekly | AZ10: =IF($A10="","",IFERROR(VLOOKUP($U10,Dim_TOP!$A:$H,8,0),"")) -> 11.65 | BA10: =IF($A10="","",IFERROR(ROUND((AH10-AZ10)*60,0),"")) -> 0 | BB10: =IF($A10="","",IF(BA10="","",IF(BA10<=0,"Sets the deadline","Later than peers by "&BA10&" min"))) -> Sets the deadline | BC10: =IF($A10="","",IF($U10="",0,IF(COUNTIFS($U$2:$U10,$U10,$C$2:$C10,$C10)=1,1,0))) -> 1 | BD10: =IF($A10="","",IF(UPPER($P10)="YES","Yes","No")) -> Yes | BE10: =IF($A10="","",IF($N10="No","n/a",IF(AM10<=Constants!$B$17,"Yes","No"))) -> No | BF10: =IF($A10="","",IF($O10="No","n/a",IF(AN10<=Constants!$B$17,"Yes","No"))) -> n/a | BG10: =IF($A10="","",IF($P10="No","n/a",IF(AO10<=Constants!$B$17,"Yes","No"))) -> No | BH10: =IF($A10="","",IF($N10="No","No custody process",IF(BE10="Yes","Thin custody slack","Ample custody slack"))) -> Ample custody slack | BI10: =IF($A10="","",IF($N10="No","",AM10)) -> 441 | BJ10: =IF($A10="","",IF($O10="No","",AN10)) | BK10: =IF($A10="","",IF($P10="No","",AO10)) -> 254
A11: FD-1010 | B11: Sample Fund 1010 | C11: CL01 | D11: Meridian Pensions | E11: Yes | F11: TM03 | G11: Chen Xiao | H11: 1.091 | I11: 0 | J11: 0 | K11: 0 | L11: 0 | M11: 0 | N11: Yes | O11: Yes | P11: Yes | Q11: 0.165311 | R11: 0.153869 | S11: 0.35369601 | T11: 0.57737416 | U11: TOP-FI1 | V11: 0.73003046 | W11: 0.76278839 | X11: Client | Y11: Confirmed | Z11: =IF($A11="","",Constants!$B$6+$I11*Constants!$B$7+$J11*Constants!$B$8+$K11*Constants!$B$9+$L11*Constants!$B$10+$M11*Constants!$B$11) -> 60 | AA11: =IF($A11="","",100-Z11) -> 40 | AB11: =IF($A11="","",ROUND($H11*Constants!$B$4,1)) -> 24.1 | AC11: =IF($A11="","",ROUND(AB11*Z11/100,1)) -> 14.5 | AD11: =IF($A11="","",ROUND(AB11*AA11/100,1)) -> 9.6 | AE11: =IF($A11="","",HOUR($Q11)+MINUTE($Q11)/60) -> 3.9666667 | AF11: =IF($A11="","",HOUR($R11)+MINUTE($R11)/60) -> 3.6833333 | AG11: =IF($A11="","",HOUR($S11)+MINUTE($S11)/60) -> 8.4833333 | AH11: =IF($A11="","",HOUR($T11)+MINUTE($T11)/60) -> 13.85 | AI11: =IF($A11="","",HOUR($V11)+MINUTE($V11)/60) -> 17.516667 | AJ11: =IF($A11="","",HOUR($W11)+MINUTE($W11)/60) -> 18.3 | AK11: =IF($A11="","",VLOOKUP($F11,Dim_Team!$A:$F,6,0)) -> 10 | AL11: =IF($A11="","",VLOOKUP($X11,Dim_Signoff!$A:$C,3,0)) -> 46 | AM11: =IF($A11="","",IF($N11="No","n/a",ROUND((AH11-AE11)*60,0))) -> 593 | AN11: =IF($A11="","",IF($O11="No","n/a",ROUND((AH11-AF11)*60,0))) -> 610 | AO11: =IF($A11="","",IF($P11="No","n/a",ROUND((AH11-AG11)*60,0))) -> 322 | AP11: =IF($A11="","",ROUND((AH11-AK11)*60,0)) -> 231 | AQ11: =IF($A11="","",ROUND((AI11-AH11)*60,0)) -> 220 | AR11: =IF($A11="","",IF(AP11>=AC11,"Yes","No")) -> Yes | AS11: =IF($A11="","",IF(AQ11>=AD11+AL11,"Yes","No")) -> Yes | AT11: =IF($A11="","",IF(AND(AR11="Yes",AS11="Yes"),"OK","REVIEW")) -> OK | AU11: =IF($A11="","",IF($P11="No","Not applicable",IF(AO11<Constants!$B$14,"CAPTURE","Not needed"))) -> Not needed | AV11: =IF($A11="","",IF($P11="No","n/a",RANK(AO11,AO:AO,1))) -> 9 | AW11: =IF($A11="","",IF(UPPER($E11)="YES","Strategic","Non-strategic")) -> Strategic | AX11: =IF($A11="","",COUNTIFS(Fact_Work!$C:$C,$A11)) -> 1 | AY11: =IF($A11="","",IF(AX11=0,"Not seen",IF(AX11>=Constants!$B$13*0.6,"Daily",IF(AX11>=Constants!$B$13*0.12,"Weekly","Monthly or ad hoc")))) -> Weekly | AZ11: =IF($A11="","",IFERROR(VLOOKUP($U11,Dim_TOP!$A:$H,8,0),"")) -> 12.45 | BA11: =IF($A11="","",IFERROR(ROUND((AH11-AZ11)*60,0),"")) -> 84 | BB11: =IF($A11="","",IF(BA11="","",IF(BA11<=0,"Sets the deadline","Later than peers by "&BA11&" min"))) -> Later than peers by 84 min | BC11: =IF($A11="","",IF($U11="",0,IF(COUNTIFS($U$2:$U11,$U11,$C$2:$C11,$C11)=1,1,0))) -> 1 | BD11: =IF($A11="","",IF(UPPER($P11)="YES","Yes","No")) -> Yes | BE11: =IF($A11="","",IF($N11="No","n/a",IF(AM11<=Constants!$B$17,"Yes","No"))) -> No | BF11: =IF($A11="","",IF($O11="No","n/a",IF(AN11<=Constants!$B$17,"Yes","No"))) -> No | BG11: =IF($A11="","",IF($P11="No","n/a",IF(AO11<=Constants!$B$17,"Yes","No"))) -> No | BH11: =IF($A11="","",IF($N11="No","No custody process",IF(BE11="Yes","Thin custody slack","Ample custody slack"))) -> Ample custody slack | BI11: =IF($A11="","",IF($N11="No","",AM11)) -> 593 | BJ11: =IF($A11="","",IF($O11="No","",AN11)) -> 610 | BK11: =IF($A11="","",IF($P11="No","",AO11)) -> 322
A12: FD-1011 | B12: Sample Fund 1011 | C12: CL02 | D12: Northgate Insurance | E12: Yes | F12: TM03 | G12: Aisha Rahman | H12: 1.958 | I12: 1 | J12: 0 | K12: 1 | L12: 0 | M12: 1 | N12: Yes | O12: Yes | P12: Yes | Q12: 0.15596948 | R12: 0.2063501 | S12: 0.48735716 | T12: 0.50974706 | U12: TOP-MA1 | V12: 0.69843804 | W12: 0.73560451 | X12: FA | Y12: Confirmed | Z12: =IF($A12="","",Constants!$B$6+$I12*Constants!$B$7+$J12*Constants!$B$8+$K12*Constants!$B$9+$L12*Constants!$B$10+$M12*Constants!$B$11) -> 80 | AA12: =IF($A12="","",100-Z12) -> 20 | AB12: =IF($A12="","",ROUND($H12*Constants!$B$4,1)) -> 43.2 | AC12: =IF($A12="","",ROUND(AB12*Z12/100,1)) -> 34.6 | AD12: =IF($A12="","",ROUND(AB12*AA12/100,1)) -> 8.6 | AE12: =IF($A12="","",HOUR($Q12)+MINUTE($Q12)/60) -> 3.7333333 | AF12: =IF($A12="","",HOUR($R12)+MINUTE($R12)/60) -> 4.95 | AG12: =IF($A12="","",HOUR($S12)+MINUTE($S12)/60) -> 11.683333 | AH12: =IF($A12="","",HOUR($T12)+MINUTE($T12)/60) -> 12.233333 | AI12: =IF($A12="","",HOUR($V12)+MINUTE($V12)/60) -> 16.75 | AJ12: =IF($A12="","",HOUR($W12)+MINUTE($W12)/60) -> 17.65 | AK12: =IF($A12="","",VLOOKUP($F12,Dim_Team!$A:$F,6,0)) -> 10 | AL12: =IF($A12="","",VLOOKUP($X12,Dim_Signoff!$A:$C,3,0)) -> 0 | AM12: =IF($A12="","",IF($N12="No","n/a",ROUND((AH12-AE12)*60,0))) -> 510 | AN12: =IF($A12="","",IF($O12="No","n/a",ROUND((AH12-AF12)*60,0))) -> 437 | AO12: =IF($A12="","",IF($P12="No","n/a",ROUND((AH12-AG12)*60,0))) -> 33 | AP12: =IF($A12="","",ROUND((AH12-AK12)*60,0)) -> 134 | AQ12: =IF($A12="","",ROUND((AI12-AH12)*60,0)) -> 271 | AR12: =IF($A12="","",IF(AP12>=AC12,"Yes","No")) -> Yes | AS12: =IF($A12="","",IF(AQ12>=AD12+AL12,"Yes","No")) -> Yes | AT12: =IF($A12="","",IF(AND(AR12="Yes",AS12="Yes"),"OK","REVIEW")) -> OK | AU12: =IF($A12="","",IF($P12="No","Not applicable",IF(AO12<Constants!$B$14,"CAPTURE","Not needed"))) -> CAPTURE | AV12: =IF($A12="","",IF($P12="No","n/a",RANK(AO12,AO:AO,1))) -> 1 | AW12: =IF($A12="","",IF(UPPER($E12)="YES","Strategic","Non-strategic")) -> Strategic | AX12: =IF($A12="","",COUNTIFS(Fact_Work!$C:$C,$A12)) -> 1 | AY12: =IF($A12="","",IF(AX12=0,"Not seen",IF(AX12>=Constants!$B$13*0.6,"Daily",IF(AX12>=Constants!$B$13*0.12,"Weekly","Monthly or ad hoc")))) -> Weekly | AZ12: =IF($A12="","",IFERROR(VLOOKUP($U12,Dim_TOP!$A:$H,8,0),"")) -> 11.716667 | BA12: =IF($A12="","",IFERROR(ROUND((AH12-AZ12)*60,0),"")) -> 31 | BB12: =IF($A12="","",IF(BA12="","",IF(BA12<=0,"Sets the deadline","Later than peers by "&BA12&" min"))) -> Later than peers by 31 min | BC12: =IF($A12="","",IF($U12="",0,IF(COUNTIFS($U$2:$U12,$U12,$C$2:$C12,$C12)=1,1,0))) -> 1 | BD12: =IF($A12="","",IF(UPPER($P12)="YES","Yes","No")) -> Yes | BE12: =IF($A12="","",IF($N12="No","n/a",IF(AM12<=Constants!$B$17,"Yes","No"))) -> No | BF12: =IF($A12="","",IF($O12="No","n/a",IF(AN12<=Constants!$B$17,"Yes","No"))) -> No | BG12: =IF($A12="","",IF($P12="No","n/a",IF(AO12<=Constants!$B$17,"Yes","No"))) -> No | BH12: =IF($A12="","",IF($N12="No","No custody process",IF(BE12="Yes","Thin custody slack","Ample custody slack"))) -> Ample custody slack | BI12: =IF($A12="","",IF($N12="No","",AM12)) -> 510 | BJ12: =IF($A12="","",IF($O12="No","",AN12)) -> 437 | BK12: =IF($A12="","",IF($P12="No","",AO12)) -> 33
A13: FD-1012 | B13: Sample Fund 1012 | C13: CL03 | D13: Halvern Wealth | E13: No | F13: TM04 | G13: Daniel Tan | H13: 2.148 | I13: 0 | J13: 0 | K13: 0 | L13: 0 | M13: 0 | N13: Yes | O13: Yes | P13: Yes | Q13: 0.15463777 | R13: 0.22714675 | S13: 0.3283202 | T13: 0.48497524 | U13: TOP-ALT | V13: 0.62696405 | W13: 0.66154727 | X13: FA | Y13: Confirmed | Z13: =IF($A13="","",Constants!$B$6+$I13*Constants!$B$7+$J13*Constants!$B$8+$K13*Constants!$B$9+$L13*Constants!$B$10+$M13*Constants!$B$11) -> 60 | AA13: =IF($A13="","",100-Z13) -> 40 | AB13: =IF($A13="","",ROUND($H13*Constants!$B$4,1)) -> 47.4 | AC13: =IF($A13="","",ROUND(AB13*Z13/100,1)) -> 28.4 | AD13: =IF($A13="","",ROUND(AB13*AA13/100,1)) -> 19 | AE13: =IF($A13="","",HOUR($Q13)+MINUTE($Q13)/60) -> 3.7 | AF13: =IF($A13="","",HOUR($R13)+MINUTE($R13)/60) -> 5.45 | AG13: =IF($A13="","",HOUR($S13)+MINUTE($S13)/60) -> 7.8666667 | AH13: =IF($A13="","",HOUR($T13)+MINUTE($T13)/60) -> 11.633333 | AI13: =IF($A13="","",HOUR($V13)+MINUTE($V13)/60) -> 15.033333 | AJ13: =IF($A13="","",HOUR($W13)+MINUTE($W13)/60) -> 15.866667 | AK13: =IF($A13="","",VLOOKUP($F13,Dim_Team!$A:$F,6,0)) -> 9 | AL13: =IF($A13="","",VLOOKUP($X13,Dim_Signoff!$A:$C,3,0)) -> 0 | AM13: =IF($A13="","",IF($N13="No","n/a",ROUND((AH13-AE13)*60,0))) -> 476 | AN13: =IF($A13="","",IF($O13="No","n/a",ROUND((AH13-AF13)*60,0))) -> 371 | AO13: =IF($A13="","",IF($P13="No","n/a",ROUND((AH13-AG13)*60,0))) -> 226 | AP13: =IF($A13="","",ROUND((AH13-AK13)*60,0)) -> 158 | AQ13: =IF($A13="","",ROUND((AI13-AH13)*60,0)) -> 204 | AR13: =IF($A13="","",IF(AP13>=AC13,"Yes","No")) -> Yes | AS13: =IF($A13="","",IF(AQ13>=AD13+AL13,"Yes","No")) -> Yes | AT13: =IF($A13="","",IF(AND(AR13="Yes",AS13="Yes"),"OK","REVIEW")) -> OK | AU13: =IF($A13="","",IF($P13="No","Not applicable",IF(AO13<Constants!$B$14,"CAPTURE","Not needed"))) -> Not needed | AV13: =IF($A13="","",IF($P13="No","n/a",RANK(AO13,AO:AO,1))) -> 3 | AW13: =IF($A13="","",IF(UPPER($E13)="YES","Strategic","Non-strategic")) -> Non-strategic | AX13: =IF($A13="","",COUNTIFS(Fact_Work!$C:$C,$A13)) -> 1 | AY13: =IF($A13="","",IF(AX13=0,"Not seen",IF(AX13>=Constants!$B$13*0.6,"Daily",IF(AX13>=Constants!$B$13*0.12,"Weekly","Monthly or ad hoc")))) -> Weekly | AZ13: =IF($A13="","",IFERROR(VLOOKUP($U13,Dim_TOP!$A:$H,8,0),"")) -> 11.633333 | BA13: =IF($A13="","",IFERROR(ROUND((AH13-AZ13)*60,0),"")) -> 0 | BB13: =IF($A13="","",IF(BA13="","",IF(BA13<=0,"Sets the deadline","Later than peers by "&BA13&" min"))) -> Sets the deadline | BC13: =IF($A13="","",IF($U13="",0,IF(COUNTIFS($U$2:$U13,$U13,$C$2:$C13,$C13)=1,1,0))) -> 1 | BD13: =IF($A13="","",IF(UPPER($P13)="YES","Yes","No")) -> Yes | BE13: =IF($A13="","",IF($N13="No","n/a",IF(AM13<=Constants!$B$17,"Yes","No"))) -> No | BF13: =IF($A13="","",IF($O13="No","n/a",IF(AN13<=Constants!$B$17,"Yes","No"))) -> No | BG13: =IF($A13="","",IF($P13="No","n/a",IF(AO13<=Constants!$B$17,"Yes","No"))) -> No | BH13: =IF($A13="","",IF($N13="No","No custody process",IF(BE13="Yes","Thin custody slack","Ample custody slack"))) -> Ample custody slack | BI13: =IF($A13="","",IF($N13="No","",AM13)) -> 476 | BJ13: =IF($A13="","",IF($O13="No","",AN13)) -> 371 | BK13: =IF($A13="","",IF($P13="No","",AO13)) -> 226
Z14: =IF($A14="","",Constants!$B$6+$I14*Constants!$B$7+$J14*Constants!$B$8+$K14*Constants!$B$9+$L14*Constants!$B$10+$M14*Constants!$B$11) | AA14: =IF($A14="","",100-Z14) | AB14: =IF($A14="","",ROUND($H14*Constants!$B$4,1)) | AC14: =IF($A14="","",ROUND(AB14*Z14/100,1)) | AD14: =IF($A14="","",ROUND(AB14*AA14/100,1)) | AE14: =IF($A14="","",HOUR($Q14)+MINUTE($Q14)/60) | AF14: =IF($A14="","",HOUR($R14)+MINUTE($R14)/60) | AG14: =IF($A14="","",HOUR($S14)+MINUTE($S14)/60) | AH14: =IF($A14="","",HOUR($T14)+MINUTE($T14)/60) | AI14: =IF($A14="","",HOUR($V14)+MINUTE($V14)/60) | AJ14: =IF($A14="","",HOUR($W14)+MINUTE($W14)/60) | AK14: =IF($A14="","",VLOOKUP($F14,Dim_Team!$A:$F,6,0)) | AL14: =IF($A14="","",VLOOKUP($X14,Dim_Signoff!$A:$C,3,0)) | AM14: =IF($A14="","",IF($N14="No","n/a",ROUND((AH14-AE14)*60,0))) | AN14: =IF($A14="","",IF($O14="No","n/a",ROUND((AH14-AF14)*60,0))) | AO14: =IF($A14="","",IF($P14="No","n/a",ROUND((AH14-AG14)*60,0))) | AP14: =IF($A14="","",ROUND((AH14-AK14)*60,0)) | AQ14: =IF($A14="","",ROUND((AI14-AH14)*60,0)) | AR14: =IF($A14="","",IF(AP14>=AC14,"Yes","No")) | AS14: =IF($A14="","",IF(AQ14>=AD14+AL14,"Yes","No")) | AT14: =IF($A14="","",IF(AND(AR14="Yes",AS14="Yes"),"OK","REVIEW")) | AU14: =IF($A14="","",IF($P14="No","Not applicable",IF(AO14<Constants!$B$14,"CAPTURE","Not needed"))) | AV14: =IF($A14="","",IF($P14="No","n/a",RANK(AO14,AO:AO,1))) | AW14: =IF($A14="","",IF(UPPER($E14)="YES","Strategic","Non-strategic")) | AX14: =IF($A14="","",COUNTIFS(Fact_Work!$C:$C,$A14)) | AY14: =IF($A14="","",IF(AX14=0,"Not seen",IF(AX14>=Constants!$B$13*0.6,"Daily",IF(AX14>=Constants!$B$13*0.12,"Weekly","Monthly or ad hoc")))) | AZ14: =IF($A14="","",IFERROR(VLOOKUP($U14,Dim_TOP!$A:$H,8,0),"")) | BA14: =IF($A14="","",IFERROR(ROUND((AH14-AZ14)*60,0),"")) | BB14: =IF($A14="","",IF(BA14="","",IF(BA14<=0,"Sets the deadline","Later than peers by "&BA14&" min"))) | BC14: =IF($A14="","",IF($U14="",0,IF(COUNTIFS($U$2:$U14,$U14,$C$2:$C14,$C14)=1,1,0))) | BD14: =IF($A14="","",IF(UPPER($P14)="YES","Yes","No")) | BE14: =IF($A14="","",IF($N14="No","n/a",IF(AM14<=Constants!$B$17,"Yes","No"))) | BF14: =IF($A14="","",IF($O14="No","n/a",IF(AN14<=Constants!$B$17,"Yes","No"))) | BG14: =IF($A14="","",IF($P14="No","n/a",IF(AO14<=Constants!$B$17,"Yes","No"))) | BH14: =IF($A14="","",IF($N14="No","No custody process",IF(BE14="Yes","Thin custody slack","Ample custody slack"))) | BI14: =IF($A14="","",IF($N14="No","",AM14)) | BJ14: =IF($A14="","",IF($O14="No","",AN14)) | BK14: =IF($A14="","",IF($P14="No","",AO14))
Z15: =IF($A15="","",Constants!$B$6+$I15*Constants!$B$7+$J15*Constants!$B$8+$K15*Constants!$B$9+$L15*Constants!$B$10+$M15*Constants!$B$11) | AA15: =IF($A15="","",100-Z15) | AB15: =IF($A15="","",ROUND($H15*Constants!$B$4,1)) | AC15: =IF($A15="","",ROUND(AB15*Z15/100,1)) | AD15: =IF($A15="","",ROUND(AB15*AA15/100,1)) | AE15: =IF($A15="","",HOUR($Q15)+MINUTE($Q15)/60) | AF15: =IF($A15="","",HOUR($R15)+MINUTE($R15)/60) | AG15: =IF($A15="","",HOUR($S15)+MINUTE($S15)/60) | AH15: =IF($A15="","",HOUR($T15)+MINUTE($T15)/60) | AI15: =IF($A15="","",HOUR($V15)+MINUTE($V15)/60) | AJ15: =IF($A15="","",HOUR($W15)+MINUTE($W15)/60) | AK15: =IF($A15="","",VLOOKUP($F15,Dim_Team!$A:$F,6,0)) | AL15: =IF($A15="","",VLOOKUP($X15,Dim_Signoff!$A:$C,3,0)) | AM15: =IF($A15="","",IF($N15="No","n/a",ROUND((AH15-AE15)*60,0))) | AN15: =IF($A15="","",IF($O15="No","n/a",ROUND((AH15-AF15)*60,0))) | AO15: =IF($A15="","",IF($P15="No","n/a",ROUND((AH15-AG15)*60,0))) | AP15: =IF($A15="","",ROUND((AH15-AK15)*60,0)) | AQ15: =IF($A15="","",ROUND((AI15-AH15)*60,0)) | AR15: =IF($A15="","",IF(AP15>=AC15,"Yes","No")) | AS15: =IF($A15="","",IF(AQ15>=AD15+AL15,"Yes","No")) | AT15: =IF($A15="","",IF(AND(AR15="Yes",AS15="Yes"),"OK","REVIEW")) | AU15: =IF($A15="","",IF($P15="No","Not applicable",IF(AO15<Constants!$B$14,"CAPTURE","Not needed"))) | AV15: =IF($A15="","",IF($P15="No","n/a",RANK(AO15,AO:AO,1))) | AW15: =IF($A15="","",IF(UPPER($E15)="YES","Strategic","Non-strategic")) | AX15: =IF($A15="","",COUNTIFS(Fact_Work!$C:$C,$A15)) | AY15: =IF($A15="","",IF(AX15=0,"Not seen",IF(AX15>=Constants!$B$13*0.6,"Daily",IF(AX15>=Constants!$B$13*0.12,"Weekly","Monthly or ad hoc")))) | AZ15: =IF($A15="","",IFERROR(VLOOKUP($U15,Dim_TOP!$A:$H,8,0),"")) | BA15: =IF($A15="","",IFERROR(ROUND((AH15-AZ15)*60,0),"")) | BB15: =IF($A15="","",IF(BA15="","",IF(BA15<=0,"Sets the deadline","Later than peers by "&BA15&" min"))) | BC15: =IF($A15="","",IF($U15="",0,IF(COUNTIFS($U$2:$U15,$U15,$C$2:$C15,$C15)=1,1,0))) | BD15: =IF($A15="","",IF(UPPER($P15)="YES","Yes","No")) | BE15: =IF($A15="","",IF($N15="No","n/a",IF(AM15<=Constants!$B$17,"Yes","No"))) | BF15: =IF($A15="","",IF($O15="No","n/a",IF(AN15<=Constants!$B$17,"Yes","No"))) | BG15: =IF($A15="","",IF($P15="No","n/a",IF(AO15<=Constants!$B$17,"Yes","No"))) | BH15: =IF($A15="","",IF($N15="No","No custody process",IF(BE15="Yes","Thin custody slack","Ample custody slack"))) | BI15: =IF($A15="","",IF($N15="No","",AM15)) | BJ15: =IF($A15="","",IF($O15="No","",AN15)) | BK15: =IF($A15="","",IF($P15="No","",AO15))
Z16: =IF($A16="","",Constants!$B$6+$I16*Constants!$B$7+$J16*Constants!$B$8+$K16*Constants!$B$9+$L16*Constants!$B$10+$M16*Constants!$B$11) | AA16: =IF($A16="","",100-Z16) | AB16: =IF($A16="","",ROUND($H16*Constants!$B$4,1)) | AC16: =IF($A16="","",ROUND(AB16*Z16/100,1)) | AD16: =IF($A16="","",ROUND(AB16*AA16/100,1)) | AE16: =IF($A16="","",HOUR($Q16)+MINUTE($Q16)/60) | AF16: =IF($A16="","",HOUR($R16)+MINUTE($R16)/60) | AG16: =IF($A16="","",HOUR($S16)+MINUTE($S16)/60) | AH16: =IF($A16="","",HOUR($T16)+MINUTE($T16)/60) | AI16: =IF($A16="","",HOUR($V16)+MINUTE($V16)/60) | AJ16: =IF($A16="","",HOUR($W16)+MINUTE($W16)/60) | AK16: =IF($A16="","",VLOOKUP($F16,Dim_Team!$A:$F,6,0)) | AL16: =IF($A16="","",VLOOKUP($X16,Dim_Signoff!$A:$C,3,0)) | AM16: =IF($A16="","",IF($N16="No","n/a",ROUND((AH16-AE16)*60,0))) | AN16: =IF($A16="","",IF($O16="No","n/a",ROUND((AH16-AF16)*60,0))) | AO16: =IF($A16="","",IF($P16="No","n/a",ROUND((AH16-AG16)*60,0))) | AP16: =IF($A16="","",ROUND((AH16-AK16)*60,0)) | AQ16: =IF($A16="","",ROUND((AI16-AH16)*60,0)) | AR16: =IF($A16="","",IF(AP16>=AC16,"Yes","No")) | AS16: =IF($A16="","",IF(AQ16>=AD16+AL16,"Yes","No")) | AT16: =IF($A16="","",IF(AND(AR16="Yes",AS16="Yes"),"OK","REVIEW")) | AU16: =IF($A16="","",IF($P16="No","Not applicable",IF(AO16<Constants!$B$14,"CAPTURE","Not needed"))) | AV16: =IF($A16="","",IF($P16="No","n/a",RANK(AO16,AO:AO,1))) | AW16: =IF($A16="","",IF(UPPER($E16)="YES","Strategic","Non-strategic")) | AX16: =IF($A16="","",COUNTIFS(Fact_Work!$C:$C,$A16)) | AY16: =IF($A16="","",IF(AX16=0,"Not seen",IF(AX16>=Constants!$B$13*0.6,"Daily",IF(AX16>=Constants!$B$13*0.12,"Weekly","Monthly or ad hoc")))) | AZ16: =IF($A16="","",IFERROR(VLOOKUP($U16,Dim_TOP!$A:$H,8,0),"")) | BA16: =IF($A16="","",IFERROR(ROUND((AH16-AZ16)*60,0),"")) | BB16: =IF($A16="","",IF(BA16="","",IF(BA16<=0,"Sets the deadline","Later than peers by "&BA16&" min"))) | BC16: =IF($A16="","",IF($U16="",0,IF(COUNTIFS($U$2:$U16,$U16,$C$2:$C16,$C16)=1,1,0))) | BD16: =IF($A16="","",IF(UPPER($P16)="YES","Yes","No")) | BE16: =IF($A16="","",IF($N16="No","n/a",IF(AM16<=Constants!$B$17,"Yes","No"))) | BF16: =IF($A16="","",IF($O16="No","n/a",IF(AN16<=Constants!$B$17,"Yes","No"))) | BG16: =IF($A16="","",IF($P16="No","n/a",IF(AO16<=Constants!$B$17,"Yes","No"))) | BH16: =IF($A16="","",IF($N16="No","No custody process",IF(BE16="Yes","Thin custody slack","Ample custody slack"))) | BI16: =IF($A16="","",IF($N16="No","",AM16)) | BJ16: =IF($A16="","",IF($O16="No","",AN16)) | BK16: =IF($A16="","",IF($P16="No","",AO16))
Z17: =IF($A17="","",Constants!$B$6+$I17*Constants!$B$7+$J17*Constants!$B$8+$K17*Constants!$B$9+$L17*Constants!$B$10+$M17*Constants!$B$11) | AA17: =IF($A17="","",100-Z17) | AB17: =IF($A17="","",ROUND($H17*Constants!$B$4,1)) | AC17: =IF($A17="","",ROUND(AB17*Z17/100,1)) | AD17: =IF($A17="","",ROUND(AB17*AA17/100,1)) | AE17: =IF($A17="","",HOUR($Q17)+MINUTE($Q17)/60) | AF17: =IF($A17="","",HOUR($R17)+MINUTE($R17)/60) | AG17: =IF($A17="","",HOUR($S17)+MINUTE($S17)/60) | AH17: =IF($A17="","",HOUR($T17)+MINUTE($T17)/60) | AI17: =IF($A17="","",HOUR($V17)+MINUTE($V17)/60) | AJ17: =IF($A17="","",HOUR($W17)+MINUTE($W17)/60) | AK17: =IF($A17="","",VLOOKUP($F17,Dim_Team!$A:$F,6,0)) | AL17: =IF($A17="","",VLOOKUP($X17,Dim_Signoff!$A:$C,3,0)) | AM17: =IF($A17="","",IF($N17="No","n/a",ROUND((AH17-AE17)*60,0))) | AN17: =IF($A17="","",IF($O17="No","n/a",ROUND((AH17-AF17)*60,0))) | AO17: =IF($A17="","",IF($P17="No","n/a",ROUND((AH17-AG17)*60,0))) | AP17: =IF($A17="","",ROUND((AH17-AK17)*60,0)) | AQ17: =IF($A17="","",ROUND((AI17-AH17)*60,0)) | AR17: =IF($A17="","",IF(AP17>=AC17,"Yes","No")) | AS17: =IF($A17="","",IF(AQ17>=AD17+AL17,"Yes","No")) | AT17: =IF($A17="","",IF(AND(AR17="Yes",AS17="Yes"),"OK","REVIEW")) | AU17: =IF($A17="","",IF($P17="No","Not applicable",IF(AO17<Constants!$B$14,"CAPTURE","Not needed"))) | AV17: =IF($A17="","",IF($P17="No","n/a",RANK(AO17,AO:AO,1))) | AW17: =IF($A17="","",IF(UPPER($E17)="YES","Strategic","Non-strategic")) | AX17: =IF($A17="","",COUNTIFS(Fact_Work!$C:$C,$A17)) | AY17: =IF($A17="","",IF(AX17=0,"Not seen",IF(AX17>=Constants!$B$13*0.6,"Daily",IF(AX17>=Constants!$B$13*0.12,"Weekly","Monthly or ad hoc")))) | AZ17: =IF($A17="","",IFERROR(VLOOKUP($U17,Dim_TOP!$A:$H,8,0),"")) | BA17: =IF($A17="","",IFERROR(ROUND((AH17-AZ17)*60,0),"")) | BB17: =IF($A17="","",IF(BA17="","",IF(BA17<=0,"Sets the deadline","Later than peers by "&BA17&" min"))) | BC17: =IF($A17="","",IF($U17="",0,IF(COUNTIFS($U$2:$U17,$U17,$C$2:$C17,$C17)=1,1,0))) | BD17: =IF($A17="","",IF(UPPER($P17)="YES","Yes","No")) | BE17: =IF($A17="","",IF($N17="No","n/a",IF(AM17<=Constants!$B$17,"Yes","No"))) | BF17: =IF($A17="","",IF($O17="No","n/a",IF(AN17<=Constants!$B$17,"Yes","No"))) | BG17: =IF($A17="","",IF($P17="No","n/a",IF(AO17<=Constants!$B$17,"Yes","No"))) | BH17: =IF($A17="","",IF($N17="No","No custody process",IF(BE17="Yes","Thin custody slack","Ample custody slack"))) | BI17: =IF($A17="","",IF($N17="No","",AM17)) | BJ17: =IF($A17="","",IF($O17="No","",AN17)) | BK17: =IF($A17="","",IF($P17="No","",AO17))
